Time slot   0
ld_routine
Time slot   1
	Loaded a process at input/proc/p0s, PID: 1 PRIO: 130
	CPU 3: Dispatched process  1
Time slot   2
liballoc:194 pid=1 pc=2 alloc reg=0 size=300 addr=0x0
print_pgtbl:
 PDG=  0x7388165db010 P4g=  0x7388165ba010 PUD=  0x738816599010 PMD=  0x738816578010
	Loaded a process at input/proc/m0s, PID: 2 PRIO: 120
	CPU 3: Put process  1 to run queue (pc=2/14)
	CPU 3: Dispatched process  1
liballoc:194 pid=1 pc=3 alloc reg=4 size=300 addr=0x12c
print_pgtbl:
 PDG=  0x7388165db010 P4g=  0x7388165ba010 PUD=  0x738816599010 PMD=  0x738816578010
	CPU 2: Dispatched process  2
liballoc:194 pid=2 pc=1 alloc reg=0 size=300 addr=0x0
print_pgtbl:
 PDG=  0x738816536010 P4g=  0x738816515010 PUD=  0x7388164f4010 PMD=  0x7388164d3010
Time slot   3
libfree:228 pid=1 pc=4 free reg=0
print_pgtbl:
 PDG=  0x7388165db010 P4g=  0x7388165ba010 PUD=  0x738816599010 PMD=  0x738816578010
liballoc:194 pid=2 pc=2 alloc reg=1 size=100 addr=0x12c
print_pgtbl:
 PDG=  0x738816536010 P4g=  0x738816515010 PUD=  0x7388164f4010 PMD=  0x7388164d3010
Time slot   4
	Loaded a process at input/proc/s3, PID: 3 PRIO: 39
	CPU 3: Put process  1 to run queue (pc=4/14)
	CPU 3: Dispatched process  1
liballoc:194 pid=1 pc=5 alloc reg=1 size=100 addr=0x0
print_pgtbl:
 PDG=  0x7388165db010 P4g=  0x7388165ba010 PUD=  0x738816599010 PMD=  0x738816578010
	CPU 2: Put process  2 to run queue (pc=2/6)
	CPU 2: Dispatched process  3
Time slot   5
	CPU 1: Dispatched process  2
libfree:228 pid=2 pc=3 free reg=0
print_pgtbl:
 PDG=  0x738816536010 P4g=  0x738816515010 PUD=  0x7388164f4010 PMD=  0x7388164d3010
	Loaded a process at input/proc/s0, PID: 4 PRIO: 38
print_pgtbl:
 PDG=  0x7388165db010 P4g=  0x7388165ba010 PUD=  0x738816599010 PMD=  0x738816578010
liballoc:194 pid=2 pc=4 alloc reg=2 size=100 addr=0x0
print_pgtbl:
 PDG=  0x738816536010 P4g=  0x738816515010 PUD=  0x7388164f4010 PMD=  0x7388164d3010
Time slot   6
	CPU 0: Dispatched process  4
	CPU 3: Put process  1 to run queue (pc=6/14)
	CPU 3: Dispatched process  1
libread:423 pid=1 pc=7 read reg=1 offset=20 data=100 dest=100
print_pgtbl:
 PDG=  0x7388165db010 P4g=  0x7388165ba010 PUD=  0x738816599010 PMD=  0x738816578010
	CPU 2: Put process  3 to run queue (pc=2/11)
	CPU 2: Dispatched process  3
	CPU 1: Put process  2 to run queue (pc=4/6)
	CPU 1: Dispatched process  2
Time slot   7
print_pgtbl:
 PDG=  0x738816536010 P4g=  0x738816515010 PUD=  0x7388164f4010 PMD=  0x7388164d3010
Time slot   8
	CPU 0: Put process  4 to run queue (pc=2/15)
	CPU 0: Dispatched process  4
	CPU 2: Put process  3 to run queue (pc=4/11)
	CPU 2: Dispatched process  3
	CPU 1: Processed  2 has finished
	CPU 3: Put process  1 to run queue (pc=8/14)
Time slot   9
	CPU 3: Dispatched process  1
	Loaded a process at input/proc/m1s, PID: 5 PRIO: 15
Time slot  10
	CPU 1: Dispatched process  5
liballoc:194 pid=5 pc=1 alloc reg=0 size=300 addr=0x0
print_pgtbl:
 PDG=  0x738814116010 P4g=  0x7388140f5010 PUD=  0x7388140d4010 PMD=  0x7388140b3010
	CPU 0: Put process  4 to run queue (pc=4/15)
	CPU 0: Dispatched process  4
	CPU 3: Put process  1 to run queue (pc=10/14)
	CPU 3: Dispatched process  1
	CPU 2: Put process  3 to run queue (pc=6/11)
	CPU 2: Dispatched process  3
liballoc:194 pid=5 pc=2 alloc reg=1 size=100 addr=0x12c
print_pgtbl:
 PDG=  0x738814116010 P4g=  0x7388140f5010 PUD=  0x7388140d4010 PMD=  0x7388140b3010
Time slot  11
	Loaded a process at input/proc/p1s, PID: 6 PRIO: 15
Time slot  12
	CPU 1: Put process  5 to run queue (pc=2/6)
	CPU 1: Dispatched process  6
	CPU 0: Put process  4 to run queue (pc=6/15)
	CPU 0: Dispatched process  5
libfree:228 pid=5 pc=3 free reg=0
print_pgtbl:
 PDG=  0x738814116010 P4g=  0x7388140f5010 PUD=  0x7388140d4010 PMD=  0x7388140b3010
	CPU 3: Put process  1 to run queue (pc=12/14)
	CPU 3: Dispatched process  4
Time slot  13
liballoc:194 pid=5 pc=4 alloc reg=2 size=100 addr=0x0
print_pgtbl:
 PDG=  0x738814116010 P4g=  0x7388140f5010 PUD=  0x7388140d4010 PMD=  0x7388140b3010
	CPU 2: Put process  3 to run queue (pc=8/11)
	CPU 2: Dispatched process  3
	Loaded a process at input/proc/s2, PID: 7 PRIO: 120
Time slot  14
	CPU 1: Put process  6 to run queue (pc=2/10)
	CPU 1: Dispatched process  7
	CPU 0: Put process  5 to run queue (pc=4/6)
	CPU 0: Dispatched process  1
libfree:228 pid=1 pc=13 free reg=4
print_pgtbl:
 PDG=  0x7388165db010 P4g=  0x7388165ba010 PUD=  0x738816599010 PMD=  0x738816578010
	CPU 2: Put process  3 to run queue (pc=10/11)
	CPU 2: Dispatched process  6
	CPU 3: Put process  4 to run queue (pc=8/15)
	CPU 3: Dispatched process  5
libfree:228 pid=5 pc=5 free reg=2
print_pgtbl:
 PDG=  0x738814116010 P4g=  0x7388140f5010 PUD=  0x7388140d4010 PMD=  0x7388140b3010
Time slot  15
libfree:228 pid=5 pc=6 free reg=1
print_pgtbl:
 PDG=  0x738814116010 P4g=  0x7388140f5010 PUD=  0x7388140d4010 PMD=  0x7388140b3010
	CPU 1: Put process  7 to run queue (pc=2/12)
	CPU 1: Dispatched process  4
Time slot  16
	CPU 0: Processed  1 has finished
	CPU 0: Dispatched process  3
	Loaded a process at input/proc/s1, PID: 8 PRIO: 0
	CPU 3: Processed  5 has finished
	CPU 3: Dispatched process  7
	CPU 2: Put process  6 to run queue (pc=4/10)
	CPU 2: Dispatched process  8
Time slot  17
	CPU 0: Processed  3 has finished
	CPU 0: Dispatched process  6
Time slot  18
	CPU 1: Put process  4 to run queue (pc=10/15)
	CPU 1: Dispatched process  4
	CPU 3: Put process  7 to run queue (pc=4/12)
	CPU 3: Dispatched process  7
	CPU 2: Put process  8 to run queue (pc=2/7)
	CPU 2: Dispatched process  8
Time slot  19
	CPU 0: Put process  6 to run queue (pc=6/10)
	CPU 0: Dispatched process  6
	CPU 1: Put process  4 to run queue (pc=12/15)
	CPU 1: Dispatched process  4
Time slot  20
	CPU 3: Put process  7 to run queue (pc=6/12)
	CPU 3: Dispatched process  7
	CPU 2: Put process  8 to run queue (pc=4/7)
	CPU 2: Dispatched process  8
Time slot  21
	CPU 0: Put process  6 to run queue (pc=8/10)
	CPU 0: Dispatched process  6
	CPU 1: Put process  4 to run queue (pc=14/15)
	CPU 1: Dispatched process  4
Time slot  22
	CPU 3: Put process  7 to run queue (pc=8/12)
	CPU 3: Dispatched process  7
	CPU 2: Put process  8 to run queue (pc=6/7)
	CPU 2: Dispatched process  8
	CPU 1: Processed  4 has finished
	CPU 1 stopped
Time slot  23
	CPU 0: Processed  6 has finished
	CPU 0 stopped
Time slot  24
	CPU 2: Processed  8 has finished
	CPU 2 stopped
Time slot  25
	CPU 3: Put process  7 to run queue (pc=10/12)
	CPU 3: Dispatched process  7
Time slot  26
Time slot  27
	CPU 3: Processed  7 has finished
	CPU 3 stopped
