Time slot   0
ld_routine
Time slot   1
Time slot   2
Time slot   3
Time slot   4
Time slot   5
	Loaded a process at input/proc/m2s, PID: 1 PRIO: 120
Time slot   6
	CPU 1: Dispatched process  1
liballoc:194 pid=1 pc=1 alloc reg=0 size=300 addr=0x0
print_pgtbl:
 PDG=  0x724571a89010 P4g=  0x724571a68010 PUD=  0x724571a47010 PMD=  0x724571a26010
Time slot   7
liballoc:194 pid=1 pc=2 alloc reg=1 size=100 addr=0x12c
print_pgtbl:
 PDG=  0x724571a89010 P4g=  0x724571a68010 PUD=  0x724571a47010 PMD=  0x724571a26010
	CPU 1: Put process  1 to run queue (pc=2/12)
Time slot   8
	CPU 1: Dispatched process  1
libfree:228 pid=1 pc=3 free reg=0
print_pgtbl:
 PDG=  0x724571a89010 P4g=  0x724571a68010 PUD=  0x724571a47010 PMD=  0x724571a26010
Time slot   9
	Loaded a process at input/proc/s0, PID: 2 PRIO: 38
	CPU 1: Put process  1 to run queue (pc=4/12)
	CPU 1: Dispatched process  1
Time slot  10
	CPU 3: Dispatched process  2
Time slot  11
	Loaded a process at input/proc/s3, PID: 3 PRIO: 39
	CPU 3: Put process  2 to run queue (pc=2/15)
	CPU 3: Dispatched process  2
	CPU 2: Dispatched process  3
Time slot  12
	CPU 1: Put process  1 to run queue (pc=6/12)
	CPU 1: Dispatched process  1
Time slot  13
	CPU 3: Put process  2 to run queue (pc=4/15)
	CPU 3: Dispatched process  2
	CPU 2: Put process  3 to run queue (pc=2/11)
	CPU 2: Dispatched process  3
	CPU 1: Put process  1 to run queue (pc=8/12)
	CPU 1: Dispatched process  1
Time slot  14
	Loaded a process at input/proc/m2s, PID: 4 PRIO: 15
Time slot  15
libfree:228 pid=1 pc=10 free reg=2
print_pgtbl:
 PDG=  0x724571a89010 P4g=  0x724571a68010 PUD=  0x724571a47010 PMD=  0x724571a26010
	CPU 0: Dispatched process  4
liballoc:194 pid=4 pc=1 alloc reg=0 size=300 addr=0x0
print_pgtbl:
 PDG=  0x724570672010 P4g=  0x724570651010 PUD=  0x724570630010 PMD=  0x72457060f010
	CPU 3: Put process  2 to run queue (pc=6/15)
	CPU 3: Dispatched process  2
	CPU 2: Put process  3 to run queue (pc=4/11)
	CPU 2: Dispatched process  3
Time slot  16
	CPU 1: Put process  1 to run queue (pc=10/12)
	CPU 1: Dispatched process  1
libfree:228 pid=1 pc=11 free reg=1
print_pgtbl:
 PDG=  0x724571a89010 P4g=  0x724571a68010 PUD=  0x724571a47010 PMD=  0x724571a26010
liballoc:194 pid=4 pc=2 alloc reg=1 size=100 addr=0x12c
print_pgtbl:
 PDG=  0x724570672010 P4g=  0x724570651010 PUD=  0x724570630010 PMD=  0x72457060f010
	Loaded a process at input/proc/s2, PID: 5 PRIO: 120
Time slot  17
	CPU 0: Put process  4 to run queue (pc=2/12)
	CPU 0: Dispatched process  5
	Loaded a process at input/proc/s1, PID: 6 PRIO: 0
	CPU 2: Put process  3 to run queue (pc=6/11)
	CPU 2: Dispatched process  6
Time slot  18
	CPU 1: Processed  1 has finished
	CPU 1: Dispatched process  4
libfree:228 pid=4 pc=3 free reg=0
print_pgtbl:
 PDG=  0x724570672010 P4g=  0x724570651010 PUD=  0x724570630010 PMD=  0x72457060f010
	CPU 3: Put process  2 to run queue (pc=8/15)
	CPU 3: Dispatched process  2
Time slot  19
	CPU 0: Put process  5 to run queue (pc=2/12)
	CPU 0: Dispatched process  3
	CPU 3: Put process  2 to run queue (pc=10/15)
	CPU 3: Dispatched process  5
	CPU 2: Put process  6 to run queue (pc=2/7)
	CPU 2: Dispatched process  6
	CPU 1: Put process  4 to run queue (pc=4/12)
Time slot  20
	CPU 1: Dispatched process  4
Time slot  21
	CPU 0: Put process  3 to run queue (pc=8/11)
	CPU 0: Dispatched process  2
	CPU 3: Put process  5 to run queue (pc=4/12)
	CPU 3: Dispatched process  3
	CPU 2: Put process  6 to run queue (pc=4/7)
	CPU 2: Dispatched process  5
Time slot  22
	CPU 1: Put process  4 to run queue (pc=6/12)
	CPU 1: Dispatched process  6
Time slot  23
	CPU 0: Put process  2 to run queue (pc=12/15)
	CPU 0: Dispatched process  4
	CPU 3: Put process  3 to run queue (pc=10/11)
	CPU 3: Dispatched process  2
	CPU 2: Put process  5 to run queue (pc=6/12)
	CPU 2: Dispatched process  3
	CPU 1: Put process  6 to run queue (pc=6/7)
	CPU 1: Dispatched process  5
Time slot  24
	CPU 2: Processed  3 has finished
	CPU 2: Dispatched process  6
Time slot  25
	CPU 0: Put process  4 to run queue (pc=8/12)
	CPU 0: Dispatched process  4
	CPU 3: Put process  2 to run queue (pc=14/15)
	CPU 3: Dispatched process  2
	CPU 2: Processed  6 has finished
	CPU 2 stopped
	CPU 1: Put process  5 to run queue (pc=8/12)
	CPU 1: Dispatched process  5
Time slot  26
libfree:228 pid=4 pc=10 free reg=2
print_pgtbl:
 PDG=  0x724570672010 P4g=  0x724570651010 PUD=  0x724570630010 PMD=  0x72457060f010
	CPU 3: Processed  2 has finished
Time slot  27
	CPU 3 stopped
	CPU 0: Put process  4 to run queue (pc=10/12)
	CPU 0: Dispatched process  4
libfree:228 pid=4 pc=11 free reg=1
print_pgtbl:
 PDG=  0x724570672010 P4g=  0x724570651010 PUD=  0x724570630010 PMD=  0x72457060f010
	CPU 1: Put process  5 to run queue (pc=10/12)
	CPU 1: Dispatched process  5
Time slot  28
Time slot  29
	CPU 0: Processed  4 has finished
	CPU 0 stopped
Time slot  30
	CPU 1: Processed  5 has finished
	CPU 1 stopped
